Workbook

Sheet 1-ый семестр 20252026
A1: Позиция в рейтинге | B1: ФИО | C1: Учебная группа | D1: ВИШенки | F1: Помощь ВИШ | G1: Мысли в РУТ | H1: Работа в ПЦ 07.06 | I1: Мероприятие 'Лидер ВИШ" | K1: Публикация статьи | L1: День памяти и скорби 23.06 | N1: XXVIII Петербургский международный экономический форум с 18.06-20.06 | O1: Торжественный выпуск офицеров запаса 19.06 | P1: Творческий лагерь "Молодёжь Москвы" | Q1: 03.07 - Выпускной ВИШ | R1: 04.07 - Вручение дипломов в Министерстве транспорта | S1: Концерт на Красной площади 11.06 | T1: Проектная школа | U1: Выставка "Транспорт 2030" в Манеже 07.08.2025 | V1: Посещение презентации проекта Молодежь Москвы в зале Петров 03.09 | W1: Школа активиста 04.09 | Y1: Школа кураторов 18.08-22.08 | Z1: Welcome day ВИШ 28.08 - 29.08 | AA1: Завтрак для партнеров | AB1: Презентация книги Минтранса 22.08 | AC1: День знаний 1 сентября | AD1: Выездная экскурсия | AE1: Встреча с зам. председателя Правительства РФ 15.09 | AF1: Вручение студенческих билетов ПИШ | AG1: Экскурсии 17.09 - 18.09 | AH1: Мастер-класс по вокалу 22.09 | AI1: Мастер-класс по танцам 23.09 | AJ1: Мастер-класс по актерскому мастерству 24.09 | AK1: Посещение экскурсии в компанию АИР Магистраль | AL1: ДР РУТ на Речном вокзале 27.09 | AM1: Форум о будущем городов БРИКС | AN1: Международный форум Цифровых технологий в сфере транспорта и логистики «ЦИФРОВАЯ ТРАНСПОРТАЦИЯ 2025» | AO1: Поездка в Загорянку 05.10 | AP1: Хакатон "Битва Титанов" | AQ1: Онлайн-лагерь для школьников | AR1: Поездка в Суздаль со студ. активом 3.10 - 5.10 | AS1: Номинация «Студенческое медиа года» 13.10 | AT1: Голосование (Марьина роща) | AU1: Выездной практический семинар ООО "Навгеоком" 9.10-11.10 | AV1: Фонд "Транспортные инновации Москвы" | AW1: Экскурсия в музей РУТ | AX1: Флешмоб ВДНХ | AY1: Турслет МГПУ | AZ1: Экскурсия АО "НИИАС" 15.10 | BA1: Экскурсия в Тверь 15.10-18.10 | BB1: Организация экскурсии для школьников 17.10 | BC1: Прохождение отбора в Школу лидеров изменений | BD1: Мистер и мисс студенчество молодежь Московы | BE1: Лекция "Цифровая гигиена и личная безопасность в Интернете" 16.10 | BF1: Встреча с директором ПИШ 21.10 | BG1: Мероприятие УМП (бобёр) | BH1: Дебют | BL1: Опрос Росмолодежь | BM1: VIII сезон Всероссийского образовательного проекта «Моя река» | BN1: 3 место на Всероссийских соревнований в Калининграде по водному поло | BO1: Проектные соревнования | BP1: Международный форум и выставка "Транспорт России" 13.11-2-.11 | BQ1: Лекция от МЧС 14.11 | BR1: Диалог с министром 19.11 | BS1: День работника транспорта 20.11 | BT1: Игра «Что? Где? Когда?» | BU1: Практическая поездка в Южно-Сахалинск | BW1: Мастер-класс для школьников 12.11 | BX1: Агитация в школе | BY1: Лига универов 14.11 | BZ1: Олимпиада "Я-профессионал" 1 этап | CA1: Гордость 06.11 | CC1: Хакатон «Город будущего» | CD1: ТранспАрт 19.11 | CF1: SK Challenge | CG1: Турнир по боксу памяти ЗМС ЗТ СССР Богаева И.С. (I место) | CH1: Московские студенческие спортивные игры XXXVIII (I место) | CI1: Украшение корпуса к НГ | CJ1: Фестиваль DRIVE DESIGN FEST 2025 (II место) | CK1: Плетение сетей | CL1: Дод 23.11 | CM1: Дод 9.11 | CN1: Экскурсия на завод АО "Метровагонмаш" 2.12 | CO1: Экскурсия в аудиторско-консалтинговую фирму Лузе 3.12 | CP1: Экскурсия в депо ООО "Локо Тех-Сервис" 3.12 | CQ1: Экскурсия на станцию "Москва-Пассажирская-Ярославская" 3.12 | CR1: Экскурсия в отделение Альфа Банка 9.12 | CS1: Управленческий совет 11.12 | CT1: Акция "Мандариновая ель" 12.12 | CU1: Поездка в приют "Дубровая роща" 14.12 | CV1: Благодарность ректора | CW1: Кураторство в клубе "Клавиши" | CX1: Открытый диалог с директорами ВИШ и ПИШ с активистами 21.01 | CY1: Каток ВДНХ 25.01 | DA1: Академическая д. | DB1: Новогодний корпоратив 15.01 | DE1: Открытие коворкинга Альфа-банка 27.01
A2: № П/П | D2: Накоплены в 1-ом семестре | E2: Доступны для списания | F2: Организация | G2: Организация | H2: Медиа д. | I2: Организация | J2: Творческая д. | K2: Научная д. | L2: Академическая д. | M2: Организация | N2: Организация | O2: Организация | P2: Творческая д. | Q2: Организация | R2: Организация | S2: Организация | T2: Организация | U2: Академическая д. | V2: Академическая д. | W2: Участие | X2: Организация | Y2: Организация | Z2: Организация | AA2: Организация | AB2: Академическая д. | AC2: Организация | AD2: Академическая д. | AE2: Организация | AF2: Организация | AG2: Академическая д. | AH2: Организация | AI2: Организация | AJ2: Организация | AK2: Академическая д. | AL2: Организация | AM2: Академическая д. | AN2: Академическая д. | AO2: Творчество | AP2: Проф. д | AQ2: Проф. д | AR2: Академическая д. | AS2: Волонтерская д. | AT2: Академическая д. | AU2: Академическая д. | AV2: Академическая д. | AW2: Академическая д. | AX2: Академическая д. | AY2: Спортивная д. | AZ2: Академическая д. | BA2: Академическая д. | BB2: Организация | BC2: Проф. д | BD2: Творчество | BE2: Академическая д. | BF2: Академическая д. | BG2: Организация | BH2: Академическая д. | BI2: Организация | BJ2: Творческая д. | BK2: Медиа | BL2: Академическая д. | BM2: Проф. д | BN2: Спортивная д. | BO2: Научная д. | BP2: Академическая д. | BQ2: Академическая д. | BR2: Академическая д. | BS2: Организация | BT2: Академическая д. | BU2: Организация | BV2: Проф д. | BW2: Проф. д | BX2: Организация | BY2: Спортивная д. | BZ2: Академическая д. | CA2: Организация | CB2: Научная д. | CC2: Проф. д | CD2: Творческая д. | CE2: Медиа | CF2: Медиа | CG2: Спортивная д. | CH2: Спортивная д. | CI2: Организация | CJ2: Проф. д | CK2: Волонтерская д. | CL2: Организация | CM2: Организация | CN2: Академическая д. | CO2: Академическая д. | CP2: Академическая д. | CQ2: Академическая д. | CR2: Академическая д. | CS2: Организация | CT2: Организация | CU2: Волонтерская д. | CV2: Волонтерская д. | CW2: Организация | CX2: Академическая д. | CY2: Академическая д. | CZ2: Творческая д. | DA2: Академическая д. | DB2: Организация | DC2: Творческая д. | DD2: Медиа | DE2: Академическая д.
A3: =ROW()-2 -> 1 | B3: Савин Артём Алексеевич | C3: ШТС-311 | D3: =SUM(F3:FJ3) -> 111 | E3: =VLOOKUP(B3, 'Списания ВИШенок'!$A$3:$D$1035, 4, 0) -> 669 | F3: 3 | H3: 5 | I3: 5 | Q3: 5 | X3: 5 | AB3: 3 | AC3: 4 | AE3: 4 | AN3: 8 | AQ3: 5 | BI3: 12 | BJ3: 12 | BK3: 12 | BZ3: 4 | CE3: 12 | CF3: 12
A4: =ROW()-2 -> 2 | B4: Молчанова Варвара Андреевна | C4: ШМС-311 | D4: =SUM(F4:FJ4) -> 22 | E4: =VLOOKUP(B4, 'Списания ВИШенок'!$A$3:$D$1035, 4, 0) -> 574 | F4: 7 | H4: 5 | I4: 5 | J4: 5
A5: =ROW()-2 -> 3 | B5: Зыкова Марина Андреевна | C5: ШМС-311 | D5: =SUM(F5:FJ5) -> 12 | E5: =VLOOKUP(B5, 'Списания ВИШенок'!$A$3:$D$1035, 4, 0) -> 563 | F5: 7 | AR5: 5
A6: =ROW()-2 -> 4 | B6: Дидушок Александра Александровна | C6: ШТД-211 | D6: =SUM(F6:FJ6) -> 47 | E6: =VLOOKUP(B6, 'Списания ВИШенок'!$A$3:$D$1035, 4, 0) -> 455 | F6: =5+3+5 -> 13 | I6: 5 | U6: 5 | X6: 8 | Y6: 10 | AC6: 6
A7: =ROW()-2 -> 5 | B7: Шейкман Софья Дмитриевна | C7: ШМС-212 | D7: =SUM(F7:FJ7) -> 74 | E7: =VLOOKUP(B7, 'Списания ВИШенок'!$A$3:$D$1035, 4, 0) -> 441 | I7: 5 | J7: 5 | Z7: 4 | AC7: 6 | BI7: 12 | BJ7: 12 | BL7: 3 | BO7: 8 | BQ7: 3 | BZ7: 4 | CD7: 12
A8: =ROW()-2 -> 6 | B8: Мялькин Эдуард Алексеевич | C8: ШТС-411 | D8: =SUM(F8:FJ8) -> 49 | E8: =VLOOKUP(B8, 'Списания ВИШенок'!$A$3:$D$1035, 4, 0) -> 412 | F8: 3 | O8: 5 | X8: 8 | AJ8: 5 | AY8: 4 | BI8: 12 | BJ8: 12
A9: =ROW()-2 -> 7 | B9: Казорина Евгения Андреевна | C9: ШТД-411 | D9: =SUM(F9:FJ9) -> 15 | E9: =VLOOKUP(B9, 'Списания ВИШенок'!$A$3:$D$1035, 4, 0) -> 401 | CD9: 12 | CP9: 3
A10: =ROW()-2 -> 8 | B10: Сазонов Артём Игоревич | C10: ШТС-211 | D10: =SUM(F10:FJ10) -> 113 | E10: =VLOOKUP(B10, 'Списания ВИШенок'!$A$3:$D$1035, 4, 0) -> 372 | F10: =5+5+7+3+5+7+5+5+8 -> 50 | I10: 5 | U10: 5 | Z10: 5 | AA10: 5 | AC10: 6 | AF10: 7 | BL10: 3 | BQ10: 3 | BU10: 12 | BV10: 12
A11: =ROW()-2 -> 9 | B11: Медведев Максим Геннадьевич | C11: ШТС-411 | D11: =SUM(F11:FJ11) -> 0 | E11: =VLOOKUP(B11, 'Списания ВИШенок'!$A$3:$D$1035, 4, 0) -> 370
A12: =ROW()-2 -> 10 | B12: Шандова Александра Сергеевна | C12: ШАД-211 | D12: =SUM(F12:FJ12) -> 95 | E12: =VLOOKUP(B12, 'Списания ВИШенок'!$A$3:$D$1035, 4, 0) -> 343 | I12: 5 | J12: 5 | Q12: 5 | X12: 8 | Y12: 10 | Z12: 5 | AC12: 6 | AI12: 5 | BI12: 12 | BJ12: 12 | BL12: 3 | BQ12: 3 | BZ12: 4 | CD12: 12
A13: =ROW()-2 -> 11 | B13: Иванов Дмитрий Андреевич | C13: ШИН-171 | D13: =SUM(F13:FJ13) -> 3 | E13: =VLOOKUP(B13, 'Списания ВИШенок'!$A$3:$D$1035, 4, 0) -> 332 | F13: 3
A14: =ROW()-2 -> 12 | B14: Ткачев Илья Витальевич | C14: ШАД-311 | D14: =SUM(F14:FJ14) -> 47 | E14: =VLOOKUP(B14, 'Списания ВИШенок'!$A$3:$D$1035, 4, 0) -> 313 | Q14: 5 | X14: 5 | AE14: 4 | AF14: 5 | AY14: 4 | BI14: 12 | BJ14: 12
A15: =ROW()-2 -> 13 | B15: Старостина Катарина Александровна | C15: ШАД-211 | D15: =SUM(F15:FJ15) -> 44 | E15: =VLOOKUP(B15, 'Списания ВИШенок'!$A$3:$D$1035, 4, 0) -> 302 | I15: 5 | J15: 5 | AI15: 5 | AO15: 5 | BI15: 12 | BJ15: 12
A16: =ROW()-2 -> 14 | B16: Филиппова Софья Владиславовна | C16: ШТД-411 | D16: =SUM(F16:FJ16) -> 17 | E16: =VLOOKUP(B16, 'Списания ВИШенок'!$A$3:$D$1035, 4, 0) -> 314 | H16: 5 | CD16: 12
A17: =ROW()-2 -> 15 | B17: Герасимов Никита Александрович | C17: ШМС-311 | D17: =SUM(F17:FJ17) -> 35 | E17: =VLOOKUP(B17, 'Списания ВИШенок'!$A$3:$D$1035, 4, 0) -> 330 | CS17: 8 | CU17: 8 | CX17: 5 | CY17: 3 | CZ17: 3 | DA17: 5 | DE17: 3
A18: =ROW()-2 -> 16 | B18: Булгаков Никита Александрович | C18: ШТС-311 | D18: =SUM(F18:FJ18) -> 75 | E18: =VLOOKUP(B18, 'Списания ВИШенок'!$A$3:$D$1035, 4, 0) -> 280 | H18: 5 | R18: 5 | U18: 5 | AK18: 3 | AN18: 8 | AX18: 5 | BG18: 5 | BI18: 12 | BJ18: 12 | BM18: 5 | BR18: 5 | BS18: 5
A19: =ROW()-2 -> 17 | B19: Буртасова Полина Ивановна | C19: ШТС-211 | D19: =SUM(F19:FJ19) -> 108 | E19: =VLOOKUP(B19, 'Списания ВИШенок'!$A$3:$D$1035, 4, 0) -> 256 | F19: 8 | N19: 15 | Q19: 10 | U19: 5 | X19: 8 | Y19: 10 | Z19: 5 | AA19: 5 | AB19: 3 | AC19: 7 | AF19: 7 | AJ19: 5 | AN19: 8 | BZ19: 4 | DB19: 8
A20: =ROW()-2 -> 18 | B20: Корнейчук Никита Сергеевич | C20: ШТД-211 | D20: =SUM(F20:FJ20) -> 0 | E20: =VLOOKUP(B20, 'Списания ВИШенок'!$A$3:$D$1035, 4, 0) -> 272
A21: =ROW()-2 -> 19 | B21: Аксенов Александр Иванович | C21: ШЭТ-311 | D21: =SUM(F21:FJ21) -> 74 | E21: =VLOOKUP(B21, 'Списания ВИШенок'!$A$3:$D$1035, 4, 0) -> 219 | F21: =9+4+5 -> 18 | Z21: 5 | AC21: 6 | AG21: 3 | AL21: 5 | AN21: 8 | BC21: 5 | BG21: 5 | BO21: 8 | BQ21: 3 | CI21: 8
A22: =ROW()-2 -> 20 | B22: Сорокин Денис Сергеевич | C22: ШМС-411 | D22: =SUM(F22:FJ22) -> 9 | E22: =VLOOKUP(B22, 'Списания ВИШенок'!$A$3:$D$1035, 4, 0) -> 241 | X22: 5 | BZ22: 4
A23: =ROW()-2 -> 21 | B23: Ныш Александр Александрович | C23: ШТС-411 | D23: =SUM(F23:FJ23) -> 33 | E23: =VLOOKUP(B23, 'Списания ВИШенок'!$A$3:$D$1035, 4, 0) -> 242 | X23: 5 | AY23: 4 | BI23: 8 | BJ23: 8 | CS23: 8
A24: =ROW()-2 -> 22 | B24: Зязева Александра Павловна | C24: ШМС-411 | D24: =SUM(F24:FJ24) -> 5 | E24: =VLOOKUP(B24, 'Списания ВИШенок'!$A$3:$D$1035, 4, 0) -> 225 | BR24: 5
A25: =ROW()-2 -> 23 | B25: Солдатова Екатерина Сергеевна | C25: ШТС-411 | D25: =SUM(F25:FJ25) -> 10 | E25: =VLOOKUP(B25, 'Списания ВИШенок'!$A$3:$D$1035, 4, 0) -> 222 | Q25: 5 | AA25: 5
A26: =ROW()-2 -> 24 | B26: Ивлева Александра Сергеевна | C26: ШТД-211 | D26: =SUM(F26:FJ26) -> 0 | E26: =VLOOKUP(B26, 'Списания ВИШенок'!$A$3:$D$1035, 4, 0) -> 203
A27: =ROW()-2 -> 25 | B27: Загоскин Егор Ильич | C27: ШМС-411 | D27: =SUM(F27:FJ27) -> 45 | E27: =VLOOKUP(B27, 'Списания ВИШенок'!$A$3:$D$1035, 4, 0) -> 188 | F27: 17 | X27: 5 | AB27: 3 | AY27: 4 | BI27: 8 | BJ27: 8
A28: =ROW()-2 -> 26 | B28: Сермакшев Михаил Владимирович | C28: ШТД-211 | D28: =SUM(F28:FJ28) -> 26 | E28: =VLOOKUP(B28, 'Списания ВИШенок'!$A$3:$D$1035, 4, 0) -> 201 | F28: 3 | BP28: 15 | CL28: 8
A29: =ROW()-2 -> 27 | B29: Сорокина Юлия Александровна | C29: ШЦТ-311 | D29: =SUM(F29:FJ29) -> 10 | E29: =VLOOKUP(B29, 'Списания ВИШенок'!$A$3:$D$1035, 4, 0) -> 196 | P29: 10
A30: =ROW()-2 -> 28 | B30: Куликов Антон Германович | C30: ШМС-311 | D30: =SUM(F30:FJ30) -> 5 | E30: =VLOOKUP(B30, 'Списания ВИШенок'!$A$3:$D$1035, 4, 0) -> 194 | V30: 5
A31: =ROW()-2 -> 29 | B31: Булгаков Вячеслав Витальевич | C31: ШАД-412 | D31: =SUM(F31:FJ31) -> 13 | E31: =VLOOKUP(B31, 'Списания ВИШенок'!$A$3:$D$1035, 4, 0) -> 188 | F31: =5+8 -> 13
A32: =ROW()-2 -> 30 | B32: Купцов Михаил Владимирович | C32: ШИН-171 | D32: =SUM(F32:FJ32) -> 0 | E32: =VLOOKUP(B32, 'Списания ВИШенок'!$A$3:$D$1035, 4, 0) -> 187
A33: =ROW()-2 -> 31 | B33: Гвоздовская Юлия Евгеньевна | C33: ШЭТ-311 | D33: =SUM(F33:FJ33) -> 24 | E33: =VLOOKUP(B33, 'Списания ВИШенок'!$A$3:$D$1035, 4, 0) -> 181 | BI33: 12 | BJ33: 12
A34: =ROW()-2 -> 32 | B34: Третьяков Ростислав Алексеевич | C34: ШАД-211 | D34: =SUM(F34:FJ34) -> 22 | E34: =VLOOKUP(B34, 'Списания ВИШенок'!$A$3:$D$1035, 4, 0) -> 183 | I34: 5 | J34: 5 | CD34: 12
A35: =ROW()-2 -> 33 | B35: Ильин Антон Алексеевич | C35: ШАД-412 | D35: =SUM(F35:FJ35) -> 7 | E35: =VLOOKUP(B35, 'Списания ВИШенок'!$A$3:$D$1035, 4, 0) -> 173 | AC35: 7
A36: =ROW()-2 -> 34 | B36: Доронин Егор Михайлович | C36: ШЦТ-311 | D36: =SUM(F36:FJ36) -> 4 | E36: =VLOOKUP(B36, 'Списания ВИШенок'!$A$3:$D$1035, 4, 0) -> 173 | AD36: 4
A37: =ROW()-2 -> 35 | B37: Васильева Ксения Александровна | C37: ШТД-411 | D37: =SUM(F37:FJ37) -> 0 | E37: =VLOOKUP(B37, 'Списания ВИШенок'!$A$3:$D$1035, 4, 0) -> 167
A38: =ROW()-2 -> 36 | B38: Ивочкина Анастасия Александровна | C38: ШЭТ-411 | D38: =SUM(F38:FJ38) -> 0 | E38: =VLOOKUP(B38, 'Списания ВИШенок'!$A$3:$D$1035, 4, 0) -> 166
A39: =ROW()-2 -> 37 | B39: Михайлов Андрей Александрович | C39: ШАД-412 | D39: =SUM(F39:FJ39) -> 47 | E39: =VLOOKUP(B39, 'Списания ВИШенок'!$A$3:$D$1035, 4, 0) -> 162 | AF39: 7 | AQ39: 5 | AR39: 5 | AZ39: 3 | BA39: 9 | BQ39: 3 | BR39: 5 | BS39: 5 | BW39: 5
A40: =ROW()-2 -> 38 | B40: Быкова Анастасия Петровна | C40: ШТД-411 | D40: =SUM(F40:FJ40) -> 14 | E40: =VLOOKUP(B40, 'Списания ВИШенок'!$A$3:$D$1035, 4, 0) -> 173 | CP40: 3 | CQ40: 3 | DC40: 8
...

Sheet 2-ой семестр 20252026
A1: Позиция в рейтинге | B1: ФИО | C1: Учебная группа | D1: ВИШенки | F1: Помощь ВИШ | G1: Новогодний вечер ДПИШ 15.01 | J1: Встреча О.Н, Покусаева и Д.В. Паринова со студентами-активистами ДПИШ 23.01 | K1: Встреча руководства университета с обучающимися в рамках празднования Дня российского студенчества 23.01 | L1: Встреча в формате открытого диалога с Губернатором Псковской области Михаилом Юрьевичем Ведерниковым 23.01 | M1: Поездка в приют "Дубовая роща" 31.01 | N1: Разработка ИИ-психолога-помощника в рамках ПД | O1: Разработка интерактивного управленческого дашборда для аналитического подразделения «Аэроэкспресс» в рамках ПД | P1: Мероприятие, посвященное Дню российской науки 06.02 | Q1: Стратегическая поездка Студенческого совета в Коломну 08.02 | R1: Подкаст «ВИШ в деталях» | S1: Поездка по биометрии (Кострома, Иваново, Нижний Новгород) (февраль) | T1: Сбор помощи для военнослужащих в рамках общегородской инициативы Комитета общественных связей и молодёжной политики Москвы (февраль) | U1: Акция в честь Дня всех влюбленных 13.02 | V1: Концерт, посвященный Дню защитника отечества 19.02 | X1: Масленица 19.02 | Y1: Масленица РУТ (МИИТ) 20.02 | Z1: Творческий фестиваль "Студенческая весна" Февраль-март | AC1: Мероприятие с участием первого заместителя Министра транспорта РФ К.А. Пашковым 19.02 | AD1: Награждение бойцов МСО 19.02 | AE1: Лекция от МВД о незаконном обороте наркотиков на территории ВДНХ 26.02 | AF1: Праздничная акция, приуроченная к Международному женскому дню 06.03 | AG1: Экскурсионная программа по экспозиции «Путешествие по России» в пространстве НЦ «Россия» 17.03 | AH1: Ярмарка вакансий ДПИШ 19.03 | AJ1: Расширенная коллегия Министерства транспорта Российской Федерации 20.03 | AK1: Плетение сетей (февраль) | AL1: ДОД РУТ 22.03 | AM1: ДОД РОАТ 21.03 | AN1: Дизайн Движение 21.03 | AO1: Разработка десктопного приложения RailCom — учебный симулятор для визуализации передачи и модуляции сигнала на железнодорожном транспорте | AP1: Создание инструмента для перехода станционных систем на новое оборудование | AQ1: Разработка сервиса видеоаналитики для остановок общественного транспорта | AR1: Хакатон "Дизайн Движение" (1,2 место + участие) | AS1: ХХХVIII Московские студенческие спортивные игры 21-22.03
A2: № П/П | D2: Накоплены в 2-ом семестре | E2: Доступны для списания | F2: Организация | G2: Организация | H2: Творческая д. | I2: Медиа | J2: Академическая д. | K2: Академическая д. | L2: Академическая д. | M2: Волонтерская д. | N2: Профессиональная д. | O2: Профессиональная д. | P2: Академическая д. | Q2: Академическая д. | R2: Медиа д. | S2: Академическая д. | T2: Волонтерская д. | U2: Организация | V2: Творческая д. | W2: Академическая д. | X2: Организация | Y2: Организация | Z2: Организация | AA2: Творческая д. | AB2: Медиа | AC2: Академическая д. | AD2: Волонтерская д. | AE2: Академическая д. | AF2: Организация | AG2: Академическая д. | AH2: Организация | AI2: Академическая д. | AJ2: Академическая д. | AK2: Волонтерская д. | AL2: Организация | AM2: Организация | AN2: Профессиональная д. | AO2: Профессиональная д. | AP2: Профессиональная д. | AQ2: Профессиональная д. | AR2: Профессиональная д.
A3: =ROW()-2 -> 1 | B3: Абашев Руслан Евгеньевич | C3: ШЦТ-211 | D3: =SUM(F3:FR3) -> 0 | E3: =VLOOKUP(B3, 'Списания ВИШенок'!$A$3:$D$1035, 4, 0) -> 10
A4: =ROW()-2 -> 2 | B4: Абдуллаев Сеймур Сабухиевич | C4: ШЭТ-111 | D4: =SUM(F4:FR4) -> 0 | E4: =VLOOKUP(B4, 'Списания ВИШенок'!$A$3:$D$1035, 4, 0) -> 0
A5: =ROW()-2 -> 3 | B5: Абдуллаева Сайкал Замирбековна | C5: ШТД-311 | D5: =SUM(F5:FR5) -> 0 | E5: =VLOOKUP(B5, 'Списания ВИШенок'!$A$3:$D$1035, 4, 0) -> 27
A6: =ROW()-2 -> 4 | B6: Абраамян Феликс Овикович | C6: ШАДк-111 | D6: =SUM(F6:FR6) -> 0 | E6: =VLOOKUP(B6, 'Списания ВИШенок'!$A$3:$D$1035, 4, 0) -> 0
A7: =ROW()-2 -> 5 | B7: Абраменков Антон Александрович | C7: ШМС-411 | D7: =SUM(F7:FR7) -> 0 | E7: =VLOOKUP(B7, 'Списания ВИШенок'!$A$3:$D$1035, 4, 0) -> 18
A8: =ROW()-2 -> 6 | B8: Абрамов Алексей Константинович | C8: ППС-441 | D8: =SUM(F8:FR8) -> 0 | E8: =VLOOKUP(B8, 'Списания ВИШенок'!$A$3:$D$1035, 4, 0) -> 20
A9: =ROW()-2 -> 7 | B9: Абрамова Анна Олеговна | C9: ШЦТ-111 | D9: =SUM(F9:FR9) -> 0 | E9: =VLOOKUP(B9, 'Списания ВИШенок'!$A$3:$D$1035, 4, 0) -> 9
A10: =ROW()-2 -> 8 | B10: Абросимов Никита Михайлович | C10: ПИН-171 | D10: =SUM(F10:FR10) -> 0 | E10: =VLOOKUP(B10, 'Списания ВИШенок'!$A$3:$D$1035, 4, 0) -> 44
A11: =ROW()-2 -> 9 | B11: Абросимов Никита Михайлович | C11: ПИН-171 | D11: =SUM(F11:FR11) -> 0 | E11: =VLOOKUP(B11, 'Списания ВИШенок'!$A$3:$D$1035, 4, 0) -> 44
A12: =ROW()-2 -> 10 | B12: Аверина Елизавета Алексеевна | C12: ШАД-412 | D12: =SUM(F12:FR12) -> 0 | E12: =VLOOKUP(B12, 'Списания ВИШенок'!$A$3:$D$1035, 4, 0) -> 15
A13: =ROW()-2 -> 11 | B13: Айткалиева Александра Камидуллаевна | C13: ПСЭ-441 | D13: =SUM(F13:FR13) -> 18 | E13: =VLOOKUP(B13, 'Списания ВИШенок'!$A$3:$D$1035, 4, 0) -> 43 | S13: 5 | Z13: 8 | AI13: 2 | AJ13: 3
A14: =ROW()-2 -> 12 | B14: Акимов Александр Алексеевич | C14: ШАД-311 | D14: =SUM(F14:FR14) -> 0 | E14: =VLOOKUP(B14, 'Списания ВИШенок'!$A$3:$D$1035, 4, 0) -> 21
A15: =ROW()-2 -> 13 | B15: Аккуратнова София Александровна | C15: ШМС-111 | D15: =SUM(F15:FR15) -> 2 | E15: =VLOOKUP(B15, 'Списания ВИШенок'!$A$3:$D$1035, 4, 0) -> -43 | AI15: 2
A16: =ROW()-2 -> 14 | B16: Акопян Артур Николаевич | C16: ШАДк-111 | D16: =SUM(F16:FR16) -> 0 | E16: =VLOOKUP(B16, 'Списания ВИШенок'!$A$3:$D$1035, 4, 0) -> 5
A17: =ROW()-2 -> 15 | B17: Аксенов Александр Иванович | C17: ШЭТ-311 | D17: =SUM(F17:FR17) -> 70 | E17: =VLOOKUP(B17, 'Списания ВИШенок'!$A$3:$D$1035, 4, 0) -> 219 | F17: =10+5 -> 15 | J17: 8 | K17: 3 | M17: 6 | Q17: 3 | S17: 5 | T17: 5 | X17: 5 | Z17: 8 | AC17: 2 | AF17: 5 | AI17: 2 | AJ17: 3
A18: =ROW()-2 -> 16 | B18: Алеев Андрей Романович | C18: ШАД-411 | D18: =SUM(F18:FR18) -> 0 | E18: =VLOOKUP(B18, 'Списания ВИШенок'!$A$3:$D$1035, 4, 0) -> 68
A19: =ROW()-2 -> 17 | B19: Алексеев Константин Игоревич | C19: ПСЭ-441 | D19: =SUM(F19:FR19) -> 0 | E19: =VLOOKUP(B19, 'Списания ВИШенок'!$A$3:$D$1035, 4, 0) -> #N/A
A20: =ROW()-2 -> 18 | B20: Алидарова Самира Зафидиновна | C20: ШЭТ-411 | D20: =SUM(F20:FR20) -> 0 | E20: =VLOOKUP(B20, 'Списания ВИШенок'!$A$3:$D$1035, 4, 0) -> 49
A21: =ROW()-2 -> 19 | B21: Алиев Саид Асламбекович | C21: ШМС-212 | D21: =SUM(F21:FR21) -> 0 | E21: =VLOOKUP(B21, 'Списания ВИШенок'!$A$3:$D$1035, 4, 0) -> 22
A22: =ROW()-2 -> 20 | B22: Алферов Кирилл Александрович | C22: ШАД-111 | D22: =SUM(F22:FR22) -> 0 | E22: =VLOOKUP(B22, 'Списания ВИШенок'!$A$3:$D$1035, 4, 0) -> 5
A23: =ROW()-2 -> 21 | B23: Андреев Андрей Сергеевич | C23: ШЦТ-111 | D23: =SUM(F23:FR23) -> 0 | E23: =VLOOKUP(B23, 'Списания ВИШенок'!$A$3:$D$1035, 4, 0) -> 24
A24: =ROW()-2 -> 22 | B24: Андреев Артём Игоревич | C24: ШТА-271 | D24: =SUM(F24:FR24) -> 0 | E24: =VLOOKUP(B24, 'Списания ВИШенок'!$A$3:$D$1035, 4, 0) -> -20
A25: =ROW()-2 -> 23 | B25: Андреев Даниил Игоревич | C25: ШТС-311 | D25: =SUM(F25:FR25) -> 2 | E25: =VLOOKUP(B25, 'Списания ВИШенок'!$A$3:$D$1035, 4, 0) -> 48 | AI25: 2
A26: =ROW()-2 -> 24 | B26: Андреев Иван Александрович | C26: ШАД-311 | D26: =SUM(F26:FR26) -> 0 | E26: =VLOOKUP(B26, 'Списания ВИШенок'!$A$3:$D$1035, 4, 0) -> 29
A27: =ROW()-2 -> 25 | B27: Антонов Владимир Сергеевич | C27: ШТД-211 | D27: =SUM(F27:FR27) -> 0 | E27: =VLOOKUP(B27, 'Списания ВИШенок'!$A$3:$D$1035, 4, 0) -> 13
A28: =ROW()-2 -> 26 | B28: Антонов Иван Алексеевич | C28: ПИН-171 | D28: =SUM(F28:FR28) -> 0 | E28: =VLOOKUP(B28, 'Списания ВИШенок'!$A$3:$D$1035, 4, 0) -> -42
A29: =ROW()-2 -> 27 | B29: Антонов Иван Алексеевич | C29: ПИН-171 | D29: =SUM(F29:FR29) -> 0 | E29: =VLOOKUP(B29, 'Списания ВИШенок'!$A$3:$D$1035, 4, 0) -> -42
A30: =ROW()-2 -> 28 | B30: Ануфриев Семен Михайлович | C30: ПИН-171 | D30: =SUM(F30:FR30) -> 0 | E30: =VLOOKUP(B30, 'Списания ВИШенок'!$A$3:$D$1035, 4, 0) -> 67
A31: =ROW()-2 -> 29 | B31: Ануфриев Семен Михайлович | C31: ПИН-171 | D31: =SUM(F31:FR31) -> 0 | E31: =VLOOKUP(B31, 'Списания ВИШенок'!$A$3:$D$1035, 4, 0) -> 67
A32: =ROW()-2 -> 30 | B32: Апреликова Ксения Александровна | C32: ШАД-211 | D32: =SUM(F32:FR32) -> 0 | E32: =VLOOKUP(B32, 'Списания ВИШенок'!$A$3:$D$1035, 4, 0) -> 22
A33: =ROW()-2 -> 31 | B33: Аргунов Леонид Эдуардович | C33: ШАД-412 | D33: =SUM(F33:FR33) -> 0 | E33: =VLOOKUP(B33, 'Списания ВИШенок'!$A$3:$D$1035, 4, 0) -> 42
A34: =ROW()-2 -> 32 | B34: Аржанников Семён Евгеньевич | C34: ШЦТ-311 | D34: =SUM(F34:FR34) -> 0 | E34: =VLOOKUP(B34, 'Списания ВИШенок'!$A$3:$D$1035, 4, 0) -> 15
A35: =ROW()-2 -> 33 | B35: Ароев Андрей Александрович | C35: ШАДк-111 | D35: =SUM(F35:FR35) -> 0 | E35: =VLOOKUP(B35, 'Списания ВИШенок'!$A$3:$D$1035, 4, 0) -> 0
A36: =ROW()-2 -> 34 | B36: Артемов Антон Андреевич | C36: ШМС-211 | D36: =SUM(F36:FR36) -> 0 | E36: =VLOOKUP(B36, 'Списания ВИШенок'!$A$3:$D$1035, 4, 0) -> 10
A37: =ROW()-2 -> 35 | B37: Артемова Анастасия Дмитриевна | C37: ШЦТ-311 | D37: =SUM(F37:FR37) -> 0 | E37: =VLOOKUP(B37, 'Списания ВИШенок'!$A$3:$D$1035, 4, 0) -> 30
... A39: =ROW()-2 -> 37 | B39: Асанов Артём Игоревич | C39: ШЭТ-211 | D39: =SUM(F39:FR39) -> 0 | E39: =VLOOKUP(B39, 'Списания ВИШенок'!$A$3:$D$1035, 4, 0) -> 36
A40: =ROW()-2 -> 38 | B40: Ассельборн Максим Алексеевич | C40: ШТС-111 | D40: =SUM(F40:FR40) -> 23 | E40: =VLOOKUP(B40, 'Списания ВИШенок'!$A$3:$D$1035, 4, 0) -> 62 | X40: 5 | Y40: 5 | Z40: 8 | AA40: 5
A41: =ROW()-2 -> 39 | B41: Астафьева Юлия Андреевна | C41: ШМС-112 | D41: =SUM(F41:FR41) -> 0 | E41: =VLOOKUP(B41, 'Списания ВИШенок'!$A$3:$D$1035, 4, 0) -> 0
...

Sheet Списания ВИШенок
A1: ФИО | B1: Учебная группа | C1: Накоплено ВИШенок | D1: Доступно для списания | E1: Покупки | O1: ШТРАФ (АНТИвишенки)
E2: Браслет ВИШ | F2: Блокнот ПИШ | G2: Картхолдер ПИШ | H2: Футболка ВИШ | I2: Футболка ПИШ | J2: Термокружка ПИШ | K2: Бутылка ВИШ | L2: Носки ВИШ | M2: Носки ПИШ | N2: Стикерпак ВИШ | O2: Описание | P2: Кол-во | Q2: Описание | R2: Кол-во
A3: Абашев Руслан Евгеньевич | B3: ШЦТ-211 | C3: =IF(ISNA(VLOOKUP(A3, '1-ый семестр 20252026'!$B$3:$D$1014, 3, 0)), 0, VLOOKUP(A3, '1-ый семестр 20252026'!$B$3:$D$1979, 3, 0)) + IF(ISNA(VLOOKUP(A3, '2-ой семестр 20252026'!$B$3:$D$1952, 3, 0)), 0, VLOOKUP(A3, '2-ой семестр 20252026'!$B$3:$D$1952, 3, 0)) -> 0 | D3: =IFERROR(VLOOKUP(A3,'ВИШенки за предыдущие года'!$A$2:B1035,2,0),0) + C3 - SUM(E3:AA3) -> 10
A4: Абдуллаев Сеймур Сабухиевич | B4: ШЭТ-111 | C4: =IF(ISNA(VLOOKUP(A4, '1-ый семестр 20252026'!$B$3:$D$1014, 3, 0)), 0, VLOOKUP(A4, '1-ый семестр 20252026'!$B$3:$D$1979, 3, 0)) + IF(ISNA(VLOOKUP(A4, '2-ой семестр 20252026'!$B$3:$D$1952, 3, 0)), 0, VLOOKUP(A4, '2-ой семестр 20252026'!$B$3:$D$1952, 3, 0)) -> 0 | D4: =IFERROR(VLOOKUP(A4,'ВИШенки за предыдущие года'!$A$2:B1910,2,0),0) + C4 - SUM(E4:AA4) -> 0
A5: Абдуллаева Сайкал Замирбековна | B5: ШТД-311 | C5: =IF(ISNA(VLOOKUP(A5, '1-ый семестр 20252026'!$B$3:$D$1014, 3, 0)), 0, VLOOKUP(A5, '1-ый семестр 20252026'!$B$3:$D$1979, 3, 0)) + IF(ISNA(VLOOKUP(A5, '2-ой семестр 20252026'!$B$3:$D$1952, 3, 0)), 0, VLOOKUP(A5, '2-ой семестр 20252026'!$B$3:$D$1952, 3, 0)) -> 13 | D5: =IFERROR(VLOOKUP(A5,'ВИШенки за предыдущие года'!$A$2:B1036,2,0),0) + C5 - SUM(E5:AA5) -> 27
A6: Абраамян Феликс Овикович | B6: ШАДк-111 | C6: =IF(ISNA(VLOOKUP(A6, '1-ый семестр 20252026'!$B$3:$D$1014, 3, 0)), 0, VLOOKUP(A6, '1-ый семестр 20252026'!$B$3:$D$1979, 3, 0)) + IF(ISNA(VLOOKUP(A6, '2-ой семестр 20252026'!$B$3:$D$1952, 3, 0)), 0, VLOOKUP(A6, '2-ой семестр 20252026'!$B$3:$D$1952, 3, 0)) -> 0 | D6: =IFERROR(VLOOKUP(A6,'ВИШенки за предыдущие года'!$A$2:B1716,2,0),0) + C6 - SUM(E6:AA6) -> 0
A7: Абраменков Антон Александрович | B7: ШМС-411 | C7: =IF(ISNA(VLOOKUP(A7, '1-ый семестр 20252026'!$B$3:$D$1014, 3, 0)), 0, VLOOKUP(A7, '1-ый семестр 20252026'!$B$3:$D$1979, 3, 0)) + IF(ISNA(VLOOKUP(A7, '2-ой семестр 20252026'!$B$3:$D$1952, 3, 0)), 0, VLOOKUP(A7, '2-ой семестр 20252026'!$B$3:$D$1952, 3, 0)) -> 0 | D7: =IFERROR(VLOOKUP(A7,'ВИШенки за предыдущие года'!$A$2:B1037,2,0),0) + C7 - SUM(E7:AA7) -> 18
A8: Абрамов Алексей Константинович | B8: ППС-441 | C8: =IF(ISNA(VLOOKUP(A8, '1-ый семестр 20252026'!$B$3:$D$1014, 3, 0)), 0, VLOOKUP(A8, '1-ый семестр 20252026'!$B$3:$D$1979, 3, 0)) + IF(ISNA(VLOOKUP(A8, '2-ой семестр 20252026'!$B$3:$D$1952, 3, 0)), 0, VLOOKUP(A8, '2-ой семестр 20252026'!$B$3:$D$1952, 3, 0)) -> 20 | D8: =IFERROR(VLOOKUP(A8,'ВИШенки за предыдущие года'!$A$2:B1973,2,0),0) + C8 - SUM(E8:AA8) -> 20
A9: Абрамова Анна Олеговна | B9: ШЦТ-111 | C9: =IF(ISNA(VLOOKUP(A9, '1-ый семестр 20252026'!$B$3:$D$1014, 3, 0)), 0, VLOOKUP(A9, '1-ый семестр 20252026'!$B$3:$D$1979, 3, 0)) + IF(ISNA(VLOOKUP(A9, '2-ой семестр 20252026'!$B$3:$D$1952, 3, 0)), 0, VLOOKUP(A9, '2-ой семестр 20252026'!$B$3:$D$1952, 3, 0)) -> 9 | D9: =IFERROR(VLOOKUP(A9,'ВИШенки за предыдущие года'!$A$2:B1876,2,0),0) + C9 - SUM(E9:AA9) -> 9
A10: Абросимов Никита Михайлович | B10: ПИН-171 | C10: =IF(ISNA(VLOOKUP(A10, '1-ый семестр 20252026'!$B$3:$D$1014, 3, 0)), 0, VLOOKUP(A10, '1-ый семестр 20252026'!$B$3:$D$1979, 3, 0)) + IF(ISNA(VLOOKUP(A10, '2-ой семестр 20252026'!$B$3:$D$1952, 3, 0)), 0, VLOOKUP(A10, '2-ой семестр 20252026'!$B$3:$D$1952, 3, 0)) -> 13 | D10: =IFERROR(VLOOKUP(A10,'ВИШенки за предыдущие года'!$A$2:B1616,2,0),0) + C10 - SUM(E10:AA10) -> 44
A11: Абросимов Никита Михайлович | B11: ПИН-171 | C11: =IF(ISNA(VLOOKUP(A11, '1-ый семестр 20252026'!$B$3:$D$1014, 3, 0)), 0, VLOOKUP(A11, '1-ый семестр 20252026'!$B$3:$D$1979, 3, 0)) + IF(ISNA(VLOOKUP(A11, '2-ой семестр 20252026'!$B$3:$D$1952, 3, 0)), 0, VLOOKUP(A11, '2-ой семестр 20252026'!$B$3:$D$1952, 3, 0)) -> 13 | D11: =IFERROR(VLOOKUP(A11,'ВИШенки за предыдущие года'!$A$2:B2019,2,0),0) + C11 - SUM(E11:AA11) -> 44
A12: Аверина Елизавета Алексеевна | B12: ШАД-412 | C12: =IF(ISNA(VLOOKUP(A12, '1-ый семестр 20252026'!$B$3:$D$1014, 3, 0)), 0, VLOOKUP(A12, '1-ый семестр 20252026'!$B$3:$D$1979, 3, 0)) + IF(ISNA(VLOOKUP(A12, '2-ой семестр 20252026'!$B$3:$D$1952, 3, 0)), 0, VLOOKUP(A12, '2-ой семестр 20252026'!$B$3:$D$1952, 3, 0)) -> 0 | D12: =IFERROR(VLOOKUP(A12,'ВИШенки за предыдущие года'!$A$2:B1038,2,0),0) + C12 - SUM(E12:AA12) -> 15
A13: Айткалиева Александра Камидуллаевна | B13: ПСЭ-441 | C13: =IF(ISNA(VLOOKUP(A13, '1-ый семестр 20252026'!$B$3:$D$1014, 3, 0)), 0, VLOOKUP(A13, '1-ый семестр 20252026'!$B$3:$D$1979, 3, 0)) + IF(ISNA(VLOOKUP(A13, '2-ой семестр 20252026'!$B$3:$D$1952, 3, 0)), 0, VLOOKUP(A13, '2-ой семестр 20252026'!$B$3:$D$1952, 3, 0)) -> 43 | D13: =IFERROR(VLOOKUP(A13,'ВИШенки за предыдущие года'!$A$2:B1974,2,0),0) + C13 - SUM(E13:AA13) -> 43
A14: Акимов Александр Алексеевич | B14: ШАД-311 | C14: =IF(ISNA(VLOOKUP(A14, '1-ый семестр 20252026'!$B$3:$D$1014, 3, 0)), 0, VLOOKUP(A14, '1-ый семестр 20252026'!$B$3:$D$1979, 3, 0)) + IF(ISNA(VLOOKUP(A14, '2-ой семестр 20252026'!$B$3:$D$1952, 3, 0)), 0, VLOOKUP(A14, '2-ой семестр 20252026'!$B$3:$D$1952, 3, 0)) -> 19 | D14: =IFERROR(VLOOKUP(A14,'ВИШенки за предыдущие года'!$A$2:B1039,2,0),0) + C14 - SUM(E14:AA14) -> 21
A15: Аккуратнова София Александровна | B15: ШМС-111 | C15: =IF(ISNA(VLOOKUP(A15, '1-ый семестр 20252026'!$B$3:$D$1014, 3, 0)), 0, VLOOKUP(A15, '1-ый семестр 20252026'!$B$3:$D$1979, 3, 0)) + IF(ISNA(VLOOKUP(A15, '2-ой семестр 20252026'!$B$3:$D$1952, 3, 0)), 0, VLOOKUP(A15, '2-ой семестр 20252026'!$B$3:$D$1952, 3, 0)) -> 7 | D15: =IFERROR(VLOOKUP(A15,'ВИШенки за предыдущие года'!$A$2:B1741,2,0),0) + C15 - SUM(E15:AA15) -> -43 | K15: 50
A16: Акопян Артур Николаевич | B16: ШАДк-111 | C16: =IF(ISNA(VLOOKUP(A16, '1-ый семестр 20252026'!$B$3:$D$1014, 3, 0)), 0, VLOOKUP(A16, '1-ый семестр 20252026'!$B$3:$D$1979, 3, 0)) + IF(ISNA(VLOOKUP(A16, '2-ой семестр 20252026'!$B$3:$D$1952, 3, 0)), 0, VLOOKUP(A16, '2-ой семестр 20252026'!$B$3:$D$1952, 3, 0)) -> 5 | D16: =IFERROR(VLOOKUP(A16,'ВИШенки за предыдущие года'!$A$2:B1717,2,0),0) + C16 - SUM(E16:AA16) -> 5
A17: Аксенов Александр Иванович | B17: ШЭТ-311 | C17: =IF(ISNA(VLOOKUP(A17, '1-ый семестр 20252026'!$B$3:$D$1014, 3, 0)), 0, VLOOKUP(A17, '1-ый семестр 20252026'!$B$3:$D$1979, 3, 0)) + IF(ISNA(VLOOKUP(A17, '2-ой семестр 20252026'!$B$3:$D$1952, 3, 0)), 0, VLOOKUP(A17, '2-ой семестр 20252026'!$B$3:$D$1952, 3, 0)) -> 144 | D17: =IFERROR(VLOOKUP(A17,'ВИШенки за предыдущие года'!$A$2:B1040,2,0),0) + C17 - SUM(E17:AA17) -> 219
A18: Алеев Андрей Романович | B18: ШАД-411 | C18: =IF(ISNA(VLOOKUP(A18, '1-ый семестр 20252026'!$B$3:$D$1014, 3, 0)), 0, VLOOKUP(A18, '1-ый семестр 20252026'!$B$3:$D$1979, 3, 0)) + IF(ISNA(VLOOKUP(A18, '2-ой семестр 20252026'!$B$3:$D$1952, 3, 0)), 0, VLOOKUP(A18, '2-ой семестр 20252026'!$B$3:$D$1952, 3, 0)) -> 6 | D18: =IFERROR(VLOOKUP(A18,'ВИШенки за предыдущие года'!$A$2:B1041,2,0),0) + C18 - SUM(E18:AA18) -> 68
A19: Алексеев Константин Игоревича | B19: ПСЭ-441 | C19: =IF(ISNA(VLOOKUP(A19, '1-ый семестр 20252026'!$B$3:$D$1014, 3, 0)), 0, VLOOKUP(A19, '1-ый семестр 20252026'!$B$3:$D$1979, 3, 0)) + IF(ISNA(VLOOKUP(A19, '2-ой семестр 20252026'!$B$3:$D$1952, 3, 0)), 0, VLOOKUP(A19, '2-ой семестр 20252026'!$B$3:$D$1952, 3, 0)) -> 31 | D19: =IFERROR(VLOOKUP(A19,'ВИШенки за предыдущие года'!$A$2:B1975,2,0),0) + C19 - SUM(E19:AA19) -> 31
A20: Алидарова Самира Зафидиновна | B20: ШЭТ-411 | C20: =IF(ISNA(VLOOKUP(A20, '1-ый семестр 20252026'!$B$3:$D$1014, 3, 0)), 0, VLOOKUP(A20, '1-ый семестр 20252026'!$B$3:$D$1979, 3, 0)) + IF(ISNA(VLOOKUP(A20, '2-ой семестр 20252026'!$B$3:$D$1952, 3, 0)), 0, VLOOKUP(A20, '2-ой семестр 20252026'!$B$3:$D$1952, 3, 0)) -> 0 | D20: =IFERROR(VLOOKUP(A20,'ВИШенки за предыдущие года'!$A$2:B1042,2,0),0) + C20 - SUM(E20:AA20) -> 49
A21: Алиев Саид Асламбекович | B21: ШМС-212 | C21: =IF(ISNA(VLOOKUP(A21, '1-ый семестр 20252026'!$B$3:$D$1014, 3, 0)), 0, VLOOKUP(A21, '1-ый семестр 20252026'!$B$3:$D$1979, 3, 0)) + IF(ISNA(VLOOKUP(A21, '2-ой семестр 20252026'!$B$3:$D$1952, 3, 0)), 0, VLOOKUP(A21, '2-ой семестр 20252026'!$B$3:$D$1952, 3, 0)) -> 0 | D21: =IFERROR(VLOOKUP(A21,'ВИШенки за предыдущие года'!$A$2:B1043,2,0),0) + C21 - SUM(E21:AA21) -> 22
A22: Алферов Кирилл Александрович | B22: ШАД-111 | C22: =IF(ISNA(VLOOKUP(A22, '1-ый семестр 20252026'!$B$3:$D$1014, 3, 0)), 0, VLOOKUP(A22, '1-ый семестр 20252026'!$B$3:$D$1979, 3, 0)) + IF(ISNA(VLOOKUP(A22, '2-ой семестр 20252026'!$B$3:$D$1952, 3, 0)), 0, VLOOKUP(A22, '2-ой семестр 20252026'!$B$3:$D$1952, 3, 0)) -> 5 | D22: =IFERROR(VLOOKUP(A22,'ВИШенки за предыдущие года'!$A$2:B1683,2,0),0) + C22 - SUM(E22:AA22) -> 5
A23: Андреев Андрей Сергеевич | B23: ШЦТ-111 | C23: =IF(ISNA(VLOOKUP(A23, '1-ый семестр 20252026'!$B$3:$D$1014, 3, 0)), 0, VLOOKUP(A23, '1-ый семестр 20252026'!$B$3:$D$1979, 3, 0)) + IF(ISNA(VLOOKUP(A23, '2-ой семестр 20252026'!$B$3:$D$1952, 3, 0)), 0, VLOOKUP(A23, '2-ой семестр 20252026'!$B$3:$D$1952, 3, 0)) -> 24 | D23: =IFERROR(VLOOKUP(A23,'ВИШенки за предыдущие года'!$A$2:B1877,2,0),0) + C23 - SUM(E23:AA23) -> 24
A24: Андреев Артём Игоревич | B24: ШТА-271 | C24: =IF(ISNA(VLOOKUP(A24, '1-ый семестр 20252026'!$B$3:$D$1014, 3, 0)), 0, VLOOKUP(A24, '1-ый семестр 20252026'!$B$3:$D$1979, 3, 0)) + IF(ISNA(VLOOKUP(A24, '2-ой семестр 20252026'!$B$3:$D$1952, 3, 0)), 0, VLOOKUP(A24, '2-ой семестр 20252026'!$B$3:$D$1952, 3, 0)) -> 0 | D24: =IFERROR(VLOOKUP(A24,'ВИШенки за предыдущие года'!$A$2:B1044,2,0),0) + C24 - SUM(E24:AA24) -> -20
A25: Андреев Даниил Игоревич | B25: ШТС-311 | C25: =IF(ISNA(VLOOKUP(A25, '1-ый семестр 20252026'!$B$3:$D$1014, 3, 0)), 0, VLOOKUP(A25, '1-ый семестр 20252026'!$B$3:$D$1979, 3, 0)) + IF(ISNA(VLOOKUP(A25, '2-ой семестр 20252026'!$B$3:$D$1952, 3, 0)), 0, VLOOKUP(A25, '2-ой семестр 20252026'!$B$3:$D$1952, 3, 0)) -> 2 | D25: =IFERROR(VLOOKUP(A25,'ВИШенки за предыдущие года'!$A$2:B1045,2,0),0) + C25 - SUM(E25:AA25) -> 48
A26: Андреев Иван Александрович | B26: ШАД-311 | C26: =IF(ISNA(VLOOKUP(A26, '1-ый семестр 20252026'!$B$3:$D$1014, 3, 0)), 0, VLOOKUP(A26, '1-ый семестр 20252026'!$B$3:$D$1979, 3, 0)) + IF(ISNA(VLOOKUP(A26, '2-ой семестр 20252026'!$B$3:$D$1952, 3, 0)), 0, VLOOKUP(A26, '2-ой семестр 20252026'!$B$3:$D$1952, 3, 0)) -> 0 | D26: =IFERROR(VLOOKUP(A26,'ВИШенки за предыдущие года'!$A$2:B1046,2,0),0) + C26 - SUM(E26:AA26) -> 29
A27: Антонов Владимир Сергеевич | B27: ШТД-211 | C27: =IF(ISNA(VLOOKUP(A27, '1-ый семестр 20252026'!$B$3:$D$1014, 3, 0)), 0, VLOOKUP(A27, '1-ый семестр 20252026'!$B$3:$D$1979, 3, 0)) + IF(ISNA(VLOOKUP(A27, '2-ой семестр 20252026'!$B$3:$D$1952, 3, 0)), 0, VLOOKUP(A27, '2-ой семестр 20252026'!$B$3:$D$1952, 3, 0)) -> 0 | D27: =IFERROR(VLOOKUP(A27,'ВИШенки за предыдущие года'!$A$2:B1047,2,0),0) + C27 - SUM(E27:AA27) -> 13
A28: Антонов Иван Алексеевич | B28: ПИН-171 | C28: =IF(ISNA(VLOOKUP(A28, '1-ый семестр 20252026'!$B$3:$D$1014, 3, 0)), 0, VLOOKUP(A28, '1-ый семестр 20252026'!$B$3:$D$1979, 3, 0)) + IF(ISNA(VLOOKUP(A28, '2-ой семестр 20252026'!$B$3:$D$1952, 3, 0)), 0, VLOOKUP(A28, '2-ой семестр 20252026'!$B$3:$D$1952, 3, 0)) -> 0 | D28: =IFERROR(VLOOKUP(A28,'ВИШенки за предыдущие года'!$A$2:B1617,2,0),0) + C28 - SUM(E28:AA28) -> -42
A29: Антонов Иван Алексеевич | B29: ПИН-171 | C29: =IF(ISNA(VLOOKUP(A29, '1-ый семестр 20252026'!$B$3:$D$1014, 3, 0)), 0, VLOOKUP(A29, '1-ый семестр 20252026'!$B$3:$D$1979, 3, 0)) + IF(ISNA(VLOOKUP(A29, '2-ой семестр 20252026'!$B$3:$D$1952, 3, 0)), 0, VLOOKUP(A29, '2-ой семестр 20252026'!$B$3:$D$1952, 3, 0)) -> 0 | D29: =IFERROR(VLOOKUP(A29,'ВИШенки за предыдущие года'!$A$2:B2020,2,0),0) + C29 - SUM(E29:AA29) -> -42
A30: Ануфриев Семен Михайлович | B30: ПИН-171 | C30: =IF(ISNA(VLOOKUP(A30, '1-ый семестр 20252026'!$B$3:$D$1014, 3, 0)), 0, VLOOKUP(A30, '1-ый семестр 20252026'!$B$3:$D$1979, 3, 0)) + IF(ISNA(VLOOKUP(A30, '2-ой семестр 20252026'!$B$3:$D$1952, 3, 0)), 0, VLOOKUP(A30, '2-ой семестр 20252026'!$B$3:$D$1952, 3, 0)) -> 0 | D30: =IFERROR(VLOOKUP(A30,'ВИШенки за предыдущие года'!$A$2:B1618,2,0),0) + C30 - SUM(E30:AA30) -> 67
A31: Ануфриев Семен Михайлович | B31: ПИН-171 | C31: =IF(ISNA(VLOOKUP(A31, '1-ый семестр 20252026'!$B$3:$D$1014, 3, 0)), 0, VLOOKUP(A31, '1-ый семестр 20252026'!$B$3:$D$1979, 3, 0)) + IF(ISNA(VLOOKUP(A31, '2-ой семестр 20252026'!$B$3:$D$1952, 3, 0)), 0, VLOOKUP(A31, '2-ой семестр 20252026'!$B$3:$D$1952, 3, 0)) -> 0 | D31: =IFERROR(VLOOKUP(A31,'ВИШенки за предыдущие года'!$A$2:B2021,2,0),0) + C31 - SUM(E31:AA31) -> 67
A32: Апреликова Ксения Александровна | B32: ШАД-211 | C32: =IF(ISNA(VLOOKUP(A32, '1-ый семестр 20252026'!$B$3:$D$1014, 3, 0)), 0, VLOOKUP(A32, '1-ый семестр 20252026'!$B$3:$D$1979, 3, 0)) + IF(ISNA(VLOOKUP(A32, '2-ой семестр 20252026'!$B$3:$D$1952, 3, 0)), 0, VLOOKUP(A32, '2-ой семестр 20252026'!$B$3:$D$1952, 3, 0)) -> 0 | D32: =IFERROR(VLOOKUP(A32,'ВИШенки за предыдущие года'!$A$2:B1048,2,0),0) + C32 - SUM(E32:AA32) -> 22
A33: Аргунов Леонид Эдуардович | B33: ШАД-412 | C33: =IF(ISNA(VLOOKUP(A33, '1-ый семестр 20252026'!$B$3:$D$1014, 3, 0)), 0, VLOOKUP(A33, '1-ый семестр 20252026'!$B$3:$D$1979, 3, 0)) + IF(ISNA(VLOOKUP(A33, '2-ой семестр 20252026'!$B$3:$D$1952, 3, 0)), 0, VLOOKUP(A33, '2-ой семестр 20252026'!$B$3:$D$1952, 3, 0)) -> 0 | D33: =IFERROR(VLOOKUP(A33,'ВИШенки за предыдущие года'!$A$2:B1049,2,0),0) + C33 - SUM(E33:AA33) -> 42
A34: Аржанников Семён Евгеньевич | B34: ШЦТ-311 | C34: =IF(ISNA(VLOOKUP(A34, '1-ый семестр 20252026'!$B$3:$D$1014, 3, 0)), 0, VLOOKUP(A34, '1-ый семестр 20252026'!$B$3:$D$1979, 3, 0)) + IF(ISNA(VLOOKUP(A34, '2-ой семестр 20252026'!$B$3:$D$1952, 3, 0)), 0, VLOOKUP(A34, '2-ой семестр 20252026'!$B$3:$D$1952, 3, 0)) -> 0 | D34: =IFERROR(VLOOKUP(A34,'ВИШенки за предыдущие года'!$A$2:B1050,2,0),0) + C34 - SUM(E34:AA34) -> 15
A35: Ароев Андрей Александрович | B35: ШАДк-111 | C35: =IF(ISNA(VLOOKUP(A35, '1-ый семестр 20252026'!$B$3:$D$1014, 3, 0)), 0, VLOOKUP(A35, '1-ый семестр 20252026'!$B$3:$D$1979, 3, 0)) + IF(ISNA(VLOOKUP(A35, '2-ой семестр 20252026'!$B$3:$D$1952, 3, 0)), 0, VLOOKUP(A35, '2-ой семестр 20252026'!$B$3:$D$1952, 3, 0)) -> 0 | D35: =IFERROR(VLOOKUP(A35,'ВИШенки за предыдущие года'!$A$2:B1718,2,0),0) + C35 - SUM(E35:AA35) -> 0
A36: Артемов Антон Андреевич | B36: ШМС-211 | C36: =IF(ISNA(VLOOKUP(A36, '1-ый семестр 20252026'!$B$3:$D$1014, 3, 0)), 0, VLOOKUP(A36, '1-ый семестр 20252026'!$B$3:$D$1979, 3, 0)) + IF(ISNA(VLOOKUP(A36, '2-ой семестр 20252026'!$B$3:$D$1952, 3, 0)), 0, VLOOKUP(A36, '2-ой семестр 20252026'!$B$3:$D$1952, 3, 0)) -> 0 | D36: =IFERROR(VLOOKUP(A36,'ВИШенки за предыдущие года'!$A$2:B1051,2,0),0) + C36 - SUM(E36:AA36) -> 10
A37: Артемова Анастасия Дмитриевна | B37: ШЦТ-311 | C37: =IF(ISNA(VLOOKUP(A37, '1-ый семестр 20252026'!$B$3:$D$1014, 3, 0)), 0, VLOOKUP(A37, '1-ый семестр 20252026'!$B$3:$D$1979, 3, 0)) + IF(ISNA(VLOOKUP(A37, '2-ой семестр 20252026'!$B$3:$D$1952, 3, 0)), 0, VLOOKUP(A37, '2-ой семестр 20252026'!$B$3:$D$1952, 3, 0)) -> 8 | D37: =IFERROR(VLOOKUP(A37,'ВИШенки за предыдущие года'!$A$2:B1052,2,0),0) + C37 - SUM(E37:AA37) -> 30
A38: Арцышевский Иван Сергеевич | B38: ШЭТ-111 | C38: =IF(ISNA(VLOOKUP(A38, '1-ый семестр 20252026'!$B$3:$D$1014, 3, 0)), 0, VLOOKUP(A38, '1-ый семестр 20252026'!$B$3:$D$1979, 3, 0)) + IF(ISNA(VLOOKUP(A38, '2-ой семестр 20252026'!$B$3:$D$1952, 3, 0)), 0, VLOOKUP(A38, '2-ой семестр 20252026'!$B$3:$D$1952, 3, 0)) -> 0 | D38: =IFERROR(VLOOKUP(A38,'ВИШенки за предыдущие года'!$A$2:B1911,2,0),0) + C38 - SUM(E38:AA38) -> 0
A39: Асанов Артём Игоревич | B39: ШЭТ-211 | C39: =IF(ISNA(VLOOKUP(A39, '1-ый семестр 20252026'!$B$3:$D$1014, 3, 0)), 0, VLOOKUP(A39, '1-ый семестр 20252026'!$B$3:$D$1979, 3, 0)) + IF(ISNA(VLOOKUP(A39, '2-ой семестр 20252026'!$B$3:$D$1952, 3, 0)), 0, VLOOKUP(A39, '2-ой семестр 20252026'!$B$3:$D$1952, 3, 0)) -> 17 | D39: =IFERROR(VLOOKUP(A39,'ВИШенки за предыдущие года'!$A$2:B1053,2,0),0) + C39 - SUM(E39:AA39) -> 36
A40: Ассельборн Максим Алексеевич | B40: ШТС-111 | C40: =IF(ISNA(VLOOKUP(A40, '1-ый семестр 20252026'!$B$3:$D$1014, 3, 0)), 0, VLOOKUP(A40, '1-ый семестр 20252026'!$B$3:$D$1979, 3, 0)) + IF(ISNA(VLOOKUP(A40, '2-ой семестр 20252026'!$B$3:$D$1952, 3, 0)), 0, VLOOKUP(A40, '2-ой семестр 20252026'!$B$3:$D$1952, 3, 0)) -> 62 | D40: =IFERROR(VLOOKUP(A40,'ВИШенки за предыдущие года'!$A$2:B1842,2,0),0) + C40 - SUM(E40:AA40) -> 62
...

Sheet Топ активистов
A1: № П/П | B1: ФИО активиста | C1: Учебная группа | D1: ВИШенок накоплено | E1: ВИШенок доступно для списания
A2: =ROW()-1 -> 1 | B2: Аккуратнова София Александровна | C2: ШМС-111 | D2: =IF(ISNA(VLOOKUP(B2, '1-ый семестр 20252026'!$B$3:$D$887, 3, 0)), 0, VLOOKUP(B2, '1-ый семестр 20252026'!$B$3:$D$887, 3, 0)) + IF(ISNA(VLOOKUP(B2, '2-ой семестр 20252026'!$B$3:$D$1952, 3, 0)), 0, VLOOKUP(B2, '2-ой семестр 20252026'!$B$3:$D$1952, 3, 0)) -> 2 | E2: =VLOOKUP(B2, 'Списания ВИШенок'!$A$3:$D$965, 4, 0) -> -43
A3: =ROW()-1 -> 2 | B3: Федотов Родион Маркович | C3: ШЭТ-411 | D3: =IF(ISNA(VLOOKUP(B3, '1-ый семестр 20252026'!$B$3:$D$887, 3, 0)), 0, VLOOKUP(B3, '1-ый семестр 20252026'!$B$3:$D$887, 3, 0)) + IF(ISNA(VLOOKUP(B3, '2-ой семестр 20252026'!$B$3:$D$1952, 3, 0)), 0, VLOOKUP(B3, '2-ой семестр 20252026'!$B$3:$D$1952, 3, 0)) -> 0 | E3: =VLOOKUP(B3, 'Списания ВИШенок'!$A$3:$D$965, 4, 0) -> -40
A4: =ROW()-1 -> 3 | B4: Антонов Иван Алексеевич | C4: ПИН-171 | D4: =IF(ISNA(VLOOKUP(B4, '1-ый семестр 20252026'!$B$3:$D$887, 3, 0)), 0, VLOOKUP(B4, '1-ый семестр 20252026'!$B$3:$D$887, 3, 0)) + IF(ISNA(VLOOKUP(B4, '2-ой семестр 20252026'!$B$3:$D$1952, 3, 0)), 0, VLOOKUP(B4, '2-ой семестр 20252026'!$B$3:$D$1952, 3, 0)) -> 0 | E4: =VLOOKUP(B4, 'Списания ВИШенок'!$A$3:$D$965, 4, 0) -> -42
A5: =ROW()-1 -> 4 | B5: Винокурова Валерия Викторовна | C5: ШТА-371 | D5: =IF(ISNA(VLOOKUP(B5, '1-ый семестр 20252026'!$B$3:$D$887, 3, 0)), 0, VLOOKUP(B5, '1-ый семестр 20252026'!$B$3:$D$887, 3, 0)) + IF(ISNA(VLOOKUP(B5, '2-ой семестр 20252026'!$B$3:$D$1952, 3, 0)), 0, VLOOKUP(B5, '2-ой семестр 20252026'!$B$3:$D$1952, 3, 0)) -> 0 | E5: =VLOOKUP(B5, 'Списания ВИШенок'!$A$3:$D$965, 4, 0) -> -37
A6: =ROW()-1 -> 5 | B6: Бодрягин Иван Антонович | C6: ШИН-171 | D6: =IF(ISNA(VLOOKUP(B6, '1-ый семестр 20252026'!$B$3:$D$887, 3, 0)), 0, VLOOKUP(B6, '1-ый семестр 20252026'!$B$3:$D$887, 3, 0)) + IF(ISNA(VLOOKUP(B6, '2-ой семестр 20252026'!$B$3:$D$1952, 3, 0)), 0, VLOOKUP(B6, '2-ой семестр 20252026'!$B$3:$D$1952, 3, 0)) -> 0 | E6: =VLOOKUP(B6, 'Списания ВИШенок'!$A$3:$D$965, 4, 0) -> -35
A7: =ROW()-1 -> 6 | B7: Пасечник Сергей Романович | C7: ШЦТ-311 | D7: =IF(ISNA(VLOOKUP(B7, '1-ый семестр 20252026'!$B$3:$D$887, 3, 0)), 0, VLOOKUP(B7, '1-ый семестр 20252026'!$B$3:$D$887, 3, 0)) + IF(ISNA(VLOOKUP(B7, '2-ой семестр 20252026'!$B$3:$D$1952, 3, 0)), 0, VLOOKUP(B7, '2-ой семестр 20252026'!$B$3:$D$1952, 3, 0)) -> 0 | E7: =VLOOKUP(B7, 'Списания ВИШенок'!$A$3:$D$965, 4, 0) -> -23
A8: =ROW()-1 -> 7 | B8: Крючков Иван Сергеевич | C8: ППС-441 | D8: =IF(ISNA(VLOOKUP(B8, '1-ый семестр 20252026'!$B$3:$D$1200, 3, 0)), 0, VLOOKUP(B8, '1-ый семестр 20252026'!$B$3:$D$1200, 3, 0)) + IF(ISNA(VLOOKUP(B8, '2-ой семестр 20252026'!$B$3:$D$1952, 3, 0)), 0, VLOOKUP(B8, '2-ой семестр 20252026'!$B$3:$D$1952, 3, 0)) -> 5 | E8: =VLOOKUP(B8, 'Списания ВИШенок'!$A$3:$D$1200, 4, 0) -> -25
A9: =ROW()-1 -> 8 | B9: Букаев Кирилл Андреевич | C9: ШАД-412 | D9: =IF(ISNA(VLOOKUP(B9, '1-ый семестр 20252026'!$B$3:$D$887, 3, 0)), 0, VLOOKUP(B9, '1-ый семестр 20252026'!$B$3:$D$887, 3, 0)) + IF(ISNA(VLOOKUP(B9, '2-ой семестр 20252026'!$B$3:$D$1952, 3, 0)), 0, VLOOKUP(B9, '2-ой семестр 20252026'!$B$3:$D$1952, 3, 0)) -> 0 | E9: =VLOOKUP(B9, 'Списания ВИШенок'!$A$3:$D$965, 4, 0) -> -25
A10: =ROW()-1 -> 9 | B10: Никонов Даниил Сергеевич | C10: ШМС-411 | D10: =IF(ISNA(VLOOKUP(B10, '1-ый семестр 20252026'!$B$3:$D$887, 3, 0)), 0, VLOOKUP(B10, '1-ый семестр 20252026'!$B$3:$D$887, 3, 0)) + IF(ISNA(VLOOKUP(B10, '2-ой семестр 20252026'!$B$3:$D$1952, 3, 0)), 0, VLOOKUP(B10, '2-ой семестр 20252026'!$B$3:$D$1952, 3, 0)) -> 0 | E10: =VLOOKUP(B10, 'Списания ВИШенок'!$A$3:$D$965, 4, 0) -> -24
A11: =ROW()-1 -> 10 | B11: Чечин Кирилл Михайлович | C11: ШМС-411 | D11: =IF(ISNA(VLOOKUP(B11, '1-ый семестр 20252026'!$B$3:$D$887, 3, 0)), 0, VLOOKUP(B11, '1-ый семестр 20252026'!$B$3:$D$887, 3, 0)) + IF(ISNA(VLOOKUP(B11, '2-ой семестр 20252026'!$B$3:$D$1952, 3, 0)), 0, VLOOKUP(B11, '2-ой семестр 20252026'!$B$3:$D$1952, 3, 0)) -> 0 | E11: =VLOOKUP(B11, 'Списания ВИШенок'!$A$3:$D$965, 4, 0) -> -22
A12: =ROW()-1 -> 11 | B12: Андреев Артём Игоревич | C12: ШТА-271 | D12: =IF(ISNA(VLOOKUP(B12, '1-ый семестр 20252026'!$B$3:$D$887, 3, 0)), 0, VLOOKUP(B12, '1-ый семестр 20252026'!$B$3:$D$887, 3, 0)) + IF(ISNA(VLOOKUP(B12, '2-ой семестр 20252026'!$B$3:$D$1952, 3, 0)), 0, VLOOKUP(B12, '2-ой семестр 20252026'!$B$3:$D$1952, 3, 0)) -> 0 | E12: =VLOOKUP(B12, 'Списания ВИШенок'!$A$3:$D$965, 4, 0) -> -20
A13: =ROW()-1 -> 12 | B13: Басманов Дмитрий Алексеевич | C13: ШАД-311 | D13: =IF(ISNA(VLOOKUP(B13, '1-ый семестр 20252026'!$B$3:$D$887, 3, 0)), 0, VLOOKUP(B13, '1-ый семестр 20252026'!$B$3:$D$887, 3, 0)) + IF(ISNA(VLOOKUP(B13, '2-ой семестр 20252026'!$B$3:$D$1952, 3, 0)), 0, VLOOKUP(B13, '2-ой семестр 20252026'!$B$3:$D$1952, 3, 0)) -> 0 | E13: =VLOOKUP(B13, 'Списания ВИШенок'!$A$3:$D$965, 4, 0) -> -20
A14: =ROW()-1 -> 13 | B14: Гончаренок Егор Петрович | C14: ШТА-371 | D14: =IF(ISNA(VLOOKUP(B14, '1-ый семестр 20252026'!$B$3:$D$887, 3, 0)), 0, VLOOKUP(B14, '1-ый семестр 20252026'!$B$3:$D$887, 3, 0)) + IF(ISNA(VLOOKUP(B14, '2-ой семестр 20252026'!$B$3:$D$1952, 3, 0)), 0, VLOOKUP(B14, '2-ой семестр 20252026'!$B$3:$D$1952, 3, 0)) -> 0 | E14: =VLOOKUP(B14, 'Списания ВИШенок'!$A$3:$D$965, 4, 0) -> -20
A15: =ROW()-1 -> 14 | B15: Рахматов Жавохир Ибодулла угли | C15: ШТА-271 | D15: =IF(ISNA(VLOOKUP(B15, '1-ый семестр 20252026'!$B$3:$D$887, 3, 0)), 0, VLOOKUP(B15, '1-ый семестр 20252026'!$B$3:$D$887, 3, 0)) + IF(ISNA(VLOOKUP(B15, '2-ой семестр 20252026'!$B$3:$D$1952, 3, 0)), 0, VLOOKUP(B15, '2-ой семестр 20252026'!$B$3:$D$1952, 3, 0)) -> 0 | E15: =VLOOKUP(B15, 'Списания ВИШенок'!$A$3:$D$965, 4, 0) -> -20
A16: =ROW()-1 -> 15 | B16: Сысоева Софья Олеговна | C16: ШТА-371 | D16: =IF(ISNA(VLOOKUP(B16, '1-ый семестр 20252026'!$B$3:$D$887, 3, 0)), 0, VLOOKUP(B16, '1-ый семестр 20252026'!$B$3:$D$887, 3, 0)) + IF(ISNA(VLOOKUP(B16, '2-ой семестр 20252026'!$B$3:$D$1952, 3, 0)), 0, VLOOKUP(B16, '2-ой семестр 20252026'!$B$3:$D$1952, 3, 0)) -> 0 | E16: =VLOOKUP(B16, 'Списания ВИШенок'!$A$3:$D$965, 4, 0) -> -20
A17: =ROW()-1 -> 16 | B17: Маршаха Амир Махмуд | C17: ШТА-371 | D17: =IF(ISNA(VLOOKUP(B17, '1-ый семестр 20252026'!$B$3:$D$887, 3, 0)), 0, VLOOKUP(B17, '1-ый семестр 20252026'!$B$3:$D$887, 3, 0)) + IF(ISNA(VLOOKUP(B17, '2-ой семестр 20252026'!$B$3:$D$1952, 3, 0)), 0, VLOOKUP(B17, '2-ой семестр 20252026'!$B$3:$D$1952, 3, 0)) -> 0 | E17: =VLOOKUP(B17, 'Списания ВИШенок'!$A$3:$D$965, 4, 0) -> -19
A18: =ROW()-1 -> 17 | B18: Любарчук Георгий Владиславович | C18: ШИН-171 | D18: =IF(ISNA(VLOOKUP(B18, '1-ый семестр 20252026'!$B$3:$D$887, 3, 0)), 0, VLOOKUP(B18, '1-ый семестр 20252026'!$B$3:$D$887, 3, 0)) + IF(ISNA(VLOOKUP(B18, '2-ой семестр 20252026'!$B$3:$D$1952, 3, 0)), 0, VLOOKUP(B18, '2-ой семестр 20252026'!$B$3:$D$1952, 3, 0)) -> 0 | E18: =VLOOKUP(B18, 'Списания ВИШенок'!$A$3:$D$965, 4, 0) -> -19
A19: =ROW()-1 -> 18 | B19: Дарахвелидзе Георгий Мамукович | C19: ШТД-411 | D19: =IF(ISNA(VLOOKUP(B19, '1-ый семестр 20252026'!$B$3:$D$887, 3, 0)), 0, VLOOKUP(B19, '1-ый семестр 20252026'!$B$3:$D$887, 3, 0)) + IF(ISNA(VLOOKUP(B19, '2-ой семестр 20252026'!$B$3:$D$1952, 3, 0)), 0, VLOOKUP(B19, '2-ой семестр 20252026'!$B$3:$D$1952, 3, 0)) -> 0 | E19: =VLOOKUP(B19, 'Списания ВИШенок'!$A$3:$D$965, 4, 0) -> -15
A20: =ROW()-1 -> 19 | B20: Маковский Антон Алексеевич | C20: ШТА-371 | D20: =IF(ISNA(VLOOKUP(B20, '1-ый семестр 20252026'!$B$3:$D$887, 3, 0)), 0, VLOOKUP(B20, '1-ый семестр 20252026'!$B$3:$D$887, 3, 0)) + IF(ISNA(VLOOKUP(B20, '2-ой семестр 20252026'!$B$3:$D$1952, 3, 0)), 0, VLOOKUP(B20, '2-ой семестр 20252026'!$B$3:$D$1952, 3, 0)) -> 0 | E20: =VLOOKUP(B20, 'Списания ВИШенок'!$A$3:$D$965, 4, 0) -> -15
... A31: =ROW()-1 -> 30 | B31: Рогинко Кирилл Михайлович | C31: ШТС-311 | D31: =IF(ISNA(VLOOKUP(B31, '1-ый семестр 20252026'!$B$3:$D$887, 3, 0)), 0, VLOOKUP(B31, '1-ый семестр 20252026'!$B$3:$D$887, 3, 0)) + IF(ISNA(VLOOKUP(B31, '2-ой семестр 20252026'!$B$3:$D$1952, 3, 0)), 0, VLOOKUP(B31, '2-ой семестр 20252026'!$B$3:$D$1952, 3, 0)) -> 0 | E31: =VLOOKUP(B31, 'Списания ВИШенок'!$A$3:$D$965, 4, 0) -> -8
A32: =ROW()-1 -> 31 | B32: Киселев Ярослав Артемович | C32: ППС-441 | D32: =IF(ISNA(VLOOKUP(B32, '1-ый семестр 20252026'!$B$3:$D$1200, 3, 0)), 0, VLOOKUP(B32, '1-ый семестр 20252026'!$B$3:$D$1200, 3, 0)) + IF(ISNA(VLOOKUP(B32, '2-ой семестр 20252026'!$B$3:$D$1952, 3, 0)), 0, VLOOKUP(B32, '2-ой семестр 20252026'!$B$3:$D$1952, 3, 0)) -> 23 | E32: =VLOOKUP(B32, 'Списания ВИШенок'!$A$3:$D$1200, 4, 0) -> -7
A33: =ROW()-1 -> 32 | B33: Кашия Георгий Шалвович | C33: ШЭТ-311 | D33: =IF(ISNA(VLOOKUP(B33, '1-ый семестр 20252026'!$B$3:$D$887, 3, 0)), 0, VLOOKUP(B33, '1-ый семестр 20252026'!$B$3:$D$887, 3, 0)) + IF(ISNA(VLOOKUP(B33, '2-ой семестр 20252026'!$B$3:$D$1952, 3, 0)), 0, VLOOKUP(B33, '2-ой семестр 20252026'!$B$3:$D$1952, 3, 0)) -> 0 | E33: =VLOOKUP(B33, 'Списания ВИШенок'!$A$3:$D$965, 4, 0) -> -7
A34: =ROW()-1 -> 33 | B34: Милин Владислав Сергеевич | C34: ШАД-311 | D34: =IF(ISNA(VLOOKUP(B34, '1-ый семестр 20252026'!$B$3:$D$887, 3, 0)), 0, VLOOKUP(B34, '1-ый семестр 20252026'!$B$3:$D$887, 3, 0)) + IF(ISNA(VLOOKUP(B34, '2-ой семестр 20252026'!$B$3:$D$1952, 3, 0)), 0, VLOOKUP(B34, '2-ой семестр 20252026'!$B$3:$D$1952, 3, 0)) -> 0 | E34: =VLOOKUP(B34, 'Списания ВИШенок'!$A$3:$D$965, 4, 0) -> -7
A35: =ROW()-1 -> 34 | B35: Кушнов Данила Константинович | C35: ШАД-211 | D35: =IF(ISNA(VLOOKUP(B35, '1-ый семестр 20252026'!$B$3:$D$887, 3, 0)), 0, VLOOKUP(B35, '1-ый семестр 20252026'!$B$3:$D$887, 3, 0)) + IF(ISNA(VLOOKUP(B35, '2-ой семестр 20252026'!$B$3:$D$1952, 3, 0)), 0, VLOOKUP(B35, '2-ой семестр 20252026'!$B$3:$D$1952, 3, 0)) -> 0 | E35: =VLOOKUP(B35, 'Списания ВИШенок'!$A$3:$D$965, 4, 0) -> -7
A36: =ROW()-1 -> 35 | B36: Суколенко Роман Дмитриевич | C36: ШТД-311 | D36: =IF(ISNA(VLOOKUP(B36, '1-ый семестр 20252026'!$B$3:$D$887, 3, 0)), 0, VLOOKUP(B36, '1-ый семестр 20252026'!$B$3:$D$887, 3, 0)) + IF(ISNA(VLOOKUP(B36, '2-ой семестр 20252026'!$B$3:$D$1952, 3, 0)), 0, VLOOKUP(B36, '2-ой семестр 20252026'!$B$3:$D$1952, 3, 0)) -> 0 | E36: =VLOOKUP(B36, 'Списания ВИШенок'!$A$3:$D$965, 4, 0) -> -6
A37: =ROW()-1 -> 36 | B37: Позняк Анатолий Анатольевич | C37: ШТС-211 | D37: =IF(ISNA(VLOOKUP(B37, '1-ый семестр 20252026'!$B$3:$D$887, 3, 0)), 0, VLOOKUP(B37, '1-ый семестр 20252026'!$B$3:$D$887, 3, 0)) + IF(ISNA(VLOOKUP(B37, '2-ой семестр 20252026'!$B$3:$D$1952, 3, 0)), 0, VLOOKUP(B37, '2-ой семестр 20252026'!$B$3:$D$1952, 3, 0)) -> 0 | E37: =VLOOKUP(B37, 'Списания ВИШенок'!$A$3:$D$965, 4, 0) -> -6
A38: =ROW()-1 -> 37 | B38: Клишин Илья Олегович | C38: ШМС-411 | D38: =IF(ISNA(VLOOKUP(B38, '1-ый семестр 20252026'!$B$3:$D$887, 3, 0)), 0, VLOOKUP(B38, '1-ый семестр 20252026'!$B$3:$D$887, 3, 0)) + IF(ISNA(VLOOKUP(B38, '2-ой семестр 20252026'!$B$3:$D$1952, 3, 0)), 0, VLOOKUP(B38, '2-ой семестр 20252026'!$B$3:$D$1952, 3, 0)) -> 0 | E38: =VLOOKUP(B38, 'Списания ВИШенок'!$A$3:$D$965, 4, 0) -> 6
A39: =ROW()-1 -> 38 | B39: Кутузов Андрей Сергеевич | C39: ШТА-371 | D39: =IF(ISNA(VLOOKUP(B39, '1-ый семестр 20252026'!$B$3:$D$887, 3, 0)), 0, VLOOKUP(B39, '1-ый семестр 20252026'!$B$3:$D$887, 3, 0)) + IF(ISNA(VLOOKUP(B39, '2-ой семестр 20252026'!$B$3:$D$1952, 3, 0)), 0, VLOOKUP(B39, '2-ой семестр 20252026'!$B$3:$D$1952, 3, 0)) -> 0 | E39: =VLOOKUP(B39, 'Списания ВИШенок'!$A$3:$D$965, 4, 0) -> -5
A40: =ROW()-1 -> 39 | B40: Мещеркин Илья Андреевич | C40: ШТД-311 | D40: =IF(ISNA(VLOOKUP(B40, '1-ый семестр 20252026'!$B$3:$D$887, 3, 0)), 0, VLOOKUP(B40, '1-ый семестр 20252026'!$B$3:$D$887, 3, 0)) + IF(ISNA(VLOOKUP(B40, '2-ой семестр 20252026'!$B$3:$D$1952, 3, 0)), 0, VLOOKUP(B40, '2-ой семестр 20252026'!$B$3:$D$1952, 3, 0)) -> 0 | E40: =VLOOKUP(B40, 'Списания ВИШенок'!$A$3:$D$965, 4, 0) -> -5
A41: =ROW()-1 -> 40 | B41: Саввин Дмитрий Вячеславович | C41: ШТД-211 | D41: =IF(ISNA(VLOOKUP(B41, '1-ый семестр 20252026'!$B$3:$D$887, 3, 0)), 0, VLOOKUP(B41, '1-ый семестр 20252026'!$B$3:$D$887, 3, 0)) + IF(ISNA(VLOOKUP(B41, '2-ой семестр 20252026'!$B$3:$D$1952, 3, 0)), 0, VLOOKUP(B41, '2-ой семестр 20252026'!$B$3:$D$1952, 3, 0)) -> 0 | E41: =VLOOKUP(B41, 'Списания ВИШенок'!$A$3:$D$965, 4, 0) -> -5
A42: =ROW()-1 -> 41 | B42: Семкин Иван Алексеевич | C42: ШТД-311 | D42: =IF(ISNA(VLOOKUP(B42, '1-ый семестр 20252026'!$B$3:$D$887, 3, 0)), 0, VLOOKUP(B42, '1-ый семестр 20252026'!$B$3:$D$887, 3, 0)) + IF(ISNA(VLOOKUP(B42, '2-ой семестр 20252026'!$B$3:$D$1952, 3, 0)), 0, VLOOKUP(B42, '2-ой семестр 20252026'!$B$3:$D$1952, 3, 0)) -> 0 | E42: =VLOOKUP(B42, 'Списания ВИШенок'!$A$3:$D$965, 4, 0) -> -5
A43: =ROW()-1 -> 42 | B43: Сергеев Олег Станиславович | C43: ШМС-212 | D43: =IF(ISNA(VLOOKUP(B43, '1-ый семестр 20252026'!$B$3:$D$887, 3, 0)), 0, VLOOKUP(B43, '1-ый семестр 20252026'!$B$3:$D$887, 3, 0)) + IF(ISNA(VLOOKUP(B43, '2-ой семестр 20252026'!$B$3:$D$1952, 3, 0)), 0, VLOOKUP(B43, '2-ой семестр 20252026'!$B$3:$D$1952, 3, 0)) -> 0 | E43: =VLOOKUP(B43, 'Списания ВИШенок'!$A$3:$D$965, 4, 0) -> -5
A44: =ROW()-1 -> 43 | B44: Лирник Сергей Александрович | C44: ШТА-371 | D44: =IF(ISNA(VLOOKUP(B44, '1-ый семестр 20252026'!$B$3:$D$887, 3, 0)), 0, VLOOKUP(B44, '1-ый семестр 20252026'!$B$3:$D$887, 3, 0)) + IF(ISNA(VLOOKUP(B44, '2-ой семестр 20252026'!$B$3:$D$1952, 3, 0)), 0, VLOOKUP(B44, '2-ой семестр 20252026'!$B$3:$D$1952, 3, 0)) -> 0 | E44: =VLOOKUP(B44, 'Списания ВИШенок'!$A$3:$D$965, 4, 0) -> -4
... A48: =ROW()-1 -> 47 | B48: Трусов Максим Алексеевич | C48: ШТД-411 | D48: =IF(ISNA(VLOOKUP(B48, '1-ый семестр 20252026'!$B$3:$D$887, 3, 0)), 0, VLOOKUP(B48, '1-ый семестр 20252026'!$B$3:$D$887, 3, 0)) + IF(ISNA(VLOOKUP(B48, '2-ой семестр 20252026'!$B$3:$D$1952, 3, 0)), 0, VLOOKUP(B48, '2-ой семестр 20252026'!$B$3:$D$1952, 3, 0)) -> 0 | E48: =VLOOKUP(B48, 'Списания ВИШенок'!$A$3:$D$965, 4, 0) -> -2
A49: =ROW()-1 -> 48 | B49: Кодиленко Виталий Александрович | C49: ПСЭ-441 | D49: =IF(ISNA(VLOOKUP(B49, '1-ый семестр 20252026'!$B$3:$D$1200, 3, 0)), 0, VLOOKUP(B49, '1-ый семестр 20252026'!$B$3:$D$1200, 3, 0)) + IF(ISNA(VLOOKUP(B49, '2-ой семестр 20252026'!$B$3:$D$1952, 3, 0)), 0, VLOOKUP(B49, '2-ой семестр 20252026'!$B$3:$D$1952, 3, 0)) -> 9 | E49: =VLOOKUP(B49, 'Списания ВИШенок'!$A$3:$D$1200, 4, 0) -> -1
A50: =ROW()-1 -> 49 | B50: Ларькин Сергей Семенович | C50: ШЭТ-411 | D50: =IF(ISNA(VLOOKUP(B50, '1-ый семестр 20252026'!$B$3:$D$887, 3, 0)), 0, VLOOKUP(B50, '1-ый семестр 20252026'!$B$3:$D$887, 3, 0)) + IF(ISNA(VLOOKUP(B50, '2-ой семестр 20252026'!$B$3:$D$1952, 3, 0)), 0, VLOOKUP(B50, '2-ой семестр 20252026'!$B$3:$D$1952, 3, 0)) -> 0 | E50: =VLOOKUP(B50, 'Списания ВИШенок'!$A$3:$D$965, 4, 0) -> -1
A51: =ROW()-1 -> 50 | B51: Абдуллаев Сеймур Сабухиевич | C51: ШЭТ-111 | D51: =IF(ISNA(VLOOKUP(B51, '1-ый семестр 20252026'!$B$3:$D$887, 3, 0)), 0, VLOOKUP(B51, '1-ый семестр 20252026'!$B$3:$D$887, 3, 0)) + IF(ISNA(VLOOKUP(B51, '2-ой семестр 20252026'!$B$3:$D$1952, 3, 0)), 0, VLOOKUP(B51, '2-ой семестр 20252026'!$B$3:$D$1952, 3, 0)) -> 0 | E51: =VLOOKUP(B51, 'Списания ВИШенок'!$A$3:$D$965, 4, 0) -> 0
A52: =ROW()-1 -> 51 | B52: Абраамян Феликс Овикович | C52: ШАДк-111 | D52: =IF(ISNA(VLOOKUP(B52, '1-ый семестр 20252026'!$B$3:$D$887, 3, 0)), 0, VLOOKUP(B52, '1-ый семестр 20252026'!$B$3:$D$887, 3, 0)) + IF(ISNA(VLOOKUP(B52, '2-ой семестр 20252026'!$B$3:$D$1952, 3, 0)), 0, VLOOKUP(B52, '2-ой семестр 20252026'!$B$3:$D$1952, 3, 0)) -> 0 | E52: =VLOOKUP(B52, 'Списания ВИШенок'!$A$3:$D$965, 4, 0) -> 0
A53: =ROW()-1 -> 52 | B53: Ароев Андрей Александрович | C53: ШАДк-111 | D53: =IF(ISNA(VLOOKUP(B53, '1-ый семестр 20252026'!$B$3:$D$887, 3, 0)), 0, VLOOKUP(B53, '1-ый семестр 20252026'!$B$3:$D$887, 3, 0)) + IF(ISNA(VLOOKUP(B53, '2-ой семестр 20252026'!$B$3:$D$1952, 3, 0)), 0, VLOOKUP(B53, '2-ой семестр 20252026'!$B$3:$D$1952, 3, 0)) -> 0 | E53: =VLOOKUP(B53, 'Списания ВИШенок'!$A$3:$D$965, 4, 0) -> 0
...

Sheet ВИШенки за предыдущие  года
A1: ФИО активиста | B1: ВИШенок накоплено за предыдущие года
A2: Абашев Руслан Евгеньевич | B2: 10
A3: Абдуллаева Сайкал Замирбековна | B3: 14
A4: Абраменко Андрей Сергеевич | B4: 108
A5: Абраменков Антон Александрович | B5: 18
A6: Абрамов Георгий Владимирович | B6: 9
A7: Абросимов Никита Михайлович | B7: 31
A8: Аверина Елизавета Алексеевна | B8: 15
A9: Авласенко Ангелина Геннадьевна | B9: 3
A10: Акимов Александр Алексеевич | B10: 2
A11: Акимов Антон Анатольевич | B11: 14
A12: Аксенов Александр Иванович | B12: 75
A13: Акулова Софья Викторовна | B13: 87
... A767: Ятченко Никита Денисович | B767: 53
